<robot name="turtle_robot">
    <!-- Główna baza robota (dolny walec) -->
    <link name="base_link">
        <visual>
            <geometry>
                <cylinder radius="0.085" length="0.225"/>
            </geometry>
            <material name="grey">
                <color rgba="0.5 0.5 0.5 1.0"/>
            </material>
        </visual>
        <collision>
            <geometry>
                <cylinder radius="0.085" length="0.225"/>
            </geometry>
        </collision>
        <inertial>
            <mass value="1.0"/>
            <origin xyz="0 0 0" />
            <inertia ixx="0.1" ixy="0.0" ixz="0.0" iyy="0.1" iyz="0.0" izz="0.1"/>
        </inertial>
    </link>

    <!-- Górny walec (drugi walec) -->
    <link name="upper_cylinder">
        <visual>
            <geometry>
                <cylinder radius="0.025" length="0.07"/>
            </geometry>
            <material name="blue">
                <color rgba="0.0 0.0 1.0 1.0"/>
            </material>
        </visual>
        <collision>
            <geometry>
                <cylinder radius="0.025" length="0.07"/>
            </geometry>
        </collision>
        <inertial>
            <mass value="0.2"/>
            <origin xyz="0 0 0.115" />
            <inertia ixx="0.01" ixy="0.0" ixz="0.0" iyy="0.01" iyz="0.0" izz="0.01"/>
        </inertial>
    </link>

    <!-- Połączenie głównej bazy z górnym walcem -->
    <joint name="upper_cylinder_joint" type="fixed">
        <parent link="base_link"/>
        <child link="upper_cylinder"/>
        <origin xyz="0 0 0.115" rpy="0 0 0"/>
    </joint>

    <!-- Lewe koło -->
    <link name="left_wheel">
        <visual>
            <geometry>
                <cylinder radius="0.05" length="0.02"/>
            </geometry>
            <material name="black">
                <color rgba="0.0 0.0 0.0 1.0"/>
            </material>
        </visual>
        <collision>
            <geometry>
                <cylinder radius="0.05" length="0.02"/>
            </geometry>
        </collision>
        <inertial>
            <mass value="0.1"/>
            <origin xyz="0 0 0"/>
            <inertia ixx="0.001" ixy="0.0" ixz="0.0" iyy="0.001" iyz="0.0" izz="0.001"/>
        </inertial>
    </link>

    <!-- Prawe koło -->
    <link name="right_wheel">
        <visual>
            <geometry>
                <cylinder radius="0.05" length="0.02"/>
            </geometry>
            <material name="black">
                <color rgba="0.0 0.0 0.0 1.0"/>
            </material>
        </visual>
        <collision>
            <geometry>
                <cylinder radius="0.05" length="0.02"/>
            </geometry>
        </collision>
        <inertial>
            <mass value="0.1"/>
            <origin xyz="0 0 0"/>
            <inertia ixx="0.001" ixy="0.0" ixz="0.0" iyy="0.001" iyz="0.0" izz="0.001"/>
        </inertial>
    </link>

    <!-- Połączenie lewego koła -->
    <joint name="left_wheel_joint" type="continuous">
        <parent link="base_link"/>
        <child link="left_wheel"/>
        <origin xyz="0 -0.085 -0.1125" rpy="1.5708 0 0"/>
        <axis xyz="0 0 1"/>
    </joint>

    <!-- Połączenie prawego koła -->
    <joint name="right_wheel_joint" type="continuous">
        <parent link="base_link"/>
        <child link="right_wheel"/>
        <origin xyz="0 0.085 -0.1125" rpy="1.5708 0 0"/>
        <axis xyz="0 0 1"/>
    </joint>
</robot>
